<mujoco model="planar point mass">
  <include file="./common/skybox.xml"/>
  <include file="./common/visual.xml"/>
  <include file="./common/materials.xml"/>

  <option timestep="0.02">
    <!-- <flag contact="disable"/> -->
  </option>

  <default>
    <joint type="hinge" axis="0 0 1" limited="true" range="-.29 .29" damping="0"/>
    <velocity ctrlrange="-1 1" ctrllimited="true" forcelimited="true" forcerange="-0.05 0.05"/>
    <default class="wall">
      <geom type="box" material="site"/>
    </default>
  </default>

  <worldbody>
    <light name="light" pos="0 0 1"/>
    <camera name="fixed" pos="0 0 .75" quat="1 0 0 0"/>
    <geom name="ground" type="plane" pos="0 0 0" size=".3 .3 .1" material="grid"/>
    <geom name="wall_x" type="plane" pos="-.3 0 .02" zaxis="1 0 0"  size=".02 .3 .02" material="decoration"/>
    <geom name="wall_y" type="plane" pos="0 -.3 .02" zaxis="0 1 0"  size=".3 .02 .02" material="decoration"/>
    <geom name="wall_neg_x" type="plane" pos=".3 0 .02" zaxis="-1 0 0"  size=".02 .3 .02" material="decoration"/>
    <geom name="wall_neg_y" type="plane" pos="0 .3 .02" zaxis="0 -1 0"  size=".3 .02 .02" material="decoration"/>

    <!-- <geom name="box" type="box" pos="0 0 .02" zaxis="0 0 1" size=".15 .15 .02" mass="100"/> -->

    <!-- Walls in the environment -->
    <geom name="wall_extra" class="wall" pos="0.11 0.12 .02" zaxis="0 1 0"  size=".2 .02 .02"/>
    <geom name="wall_extra_2" class="wall" pos="-0.25 0.12 .02" zaxis="0 1 0"  size=".06 .02 .02"/>


    <body name="pointmass" pos="0 0 .01">
      <camera name="cam0" pos="0 -0.3 0.3" xyaxes="1 0 0 0 0.7 0.7"/>
      <joint name="root_x" type="slide"  pos="0 0 0" axis="1 0 0" />
      <joint name="root_y" type="slide"  pos="0 0 0" axis="0 1 0" />
      <geom name="pointmass" type="sphere" size=".01" material="self" mass=".01"/>
    </body>

    <geom name="target" pos="0.23 0.23 .01" material="target" type="sphere" size="0.015" contype="0"/>
  </worldbody>

  <actuator>
    <!-- Doing <motor name="t1" joint="root_x"/> end in wall clipping -->
    <velocity name="t1" joint="root_x" kv="0.5" />
    <velocity name="t2" joint="root_y" kv="0.5" />
  </actuator>
</mujoco>
